<?xml version="1.0" ?>
<!-- =================================================================================== -->
<!-- |    This document was autogenerated by xacro from /opt/ros/noetic/share/neura_robot_description/lara5/urdf/lara5.urdf.xacro | -->
<!-- |    EDITING THIS FILE BY HAND IS NOT RECOMMENDED                                 | -->
<!-- =================================================================================== -->
<robot name="lara5" xmlns:controller="http://playerstage.sourceforge.net/gazebo/xmlschema/#controller" xmlns:interface="http://playerstage.sourceforge.net/gazebo/xmlschema/#interface" xmlns:sensor="http://playerstage.sourceforge.net/gazebo/xmlschema/#sensor">
    <!-- values not correct. 12/05/2022 heitmann-->
    <material name="white">
        <color rgba="1 1 1 1" />
    </material>
    <!-- values not correct. 12/05/2022 heitmann-->
    <!-- ============================ BASE ================================= -->
    <link name="lara5_root_link" />
    <joint name="lara5_root_joint" type="fixed">
        <origin rpy="0 -1.5707963267948966 0" xyz="0 0 0" />
        <axis xyz="0 0 1" />
        <parent link="lara5_root_link" />
        <child link="lara5_link0" />
    </joint>
    <link name="lara5_link0">
        <inertial>
            <mass value="2.133" />
            <origin rpy="0 0 0" xyz="0.0 0.0 0.0" />
            <inertia ixx="0.0" ixy="0.0" ixz="0.0" iyy="0.0" iyz="0.0" izz="0.0" />
        </inertial>
        <visual>
            <origin rpy="0 0 0" xyz="0 0 0" />
            <geometry>
                <mesh filename="package://neura_robot_description/lara5/meshes/Link0_body.stl" />
            </geometry>
            <material name="white" />
        </visual>
        <visual>
            <origin rpy="0 0 0" xyz="0 0 0" />
            <geometry>
                <mesh filename="package://neura_robot_description/lara5/meshes/Link0_connector.stl" />
            </geometry>
            <material name="white" />
        </visual>
        <collision>
            <origin rpy="0 0 0" xyz="0 0 0" />
            <geometry>
                <mesh filename="package://neura_robot_description/lara5/collision/Link0_body.stl" />
            </geometry>
            <material name="white" />
        </collision>
    </link>
    <!-- ============================ DOF1 ================================= -->
    <joint name="lara5_joint1" type="revolute">
        <origin rpy="0 0 1.5707963267948966" xyz="0.22 0 0" />
        <axis xyz="0 -1 0" />
        <limit effort="204" lower="-3.14159" upper="3.14159" velocity="3.14159" />
        <parent link="lara5_link0" />
        <child link="lara5_link1" />
    </joint>
    <link name="lara5_link1">
        <inertial>
            <mass value="7.962" />
            <origin rpy="0 0 0" xyz="0.021749 0.051099 1.2e-05" />
            <inertia ixx="0.040138" ixy="0.008898" ixz="3e-06" iyy="0.022282" iyz="2e-06" izz="0.047361" />
        </inertial>
        <visual>
            <origin rpy="0 0 0" xyz="0 0 0" />
            <geometry>
                <mesh filename="package://neura_robot_description/lara5/meshes/Link1_body.stl" />
            </geometry>
            <material name="white" />
        </visual>
        <visual>
            <origin rpy="0 0 0" xyz="0 0 0" />
            <geometry>
                <mesh filename="package://neura_robot_description/lara5/meshes/Link1_rings.stl" />
            </geometry>
            <material name="white" />
        </visual>
        <collision>
            <origin rpy="0 0 0" xyz="0 0 0" />
            <geometry>
                <mesh filename="package://neura_robot_description/lara5/collision/Link1_body.stl" />
            </geometry>
            <material name="white" />
        </collision>
    </link>
    <!-- ============================ DOF2 ================================= -->
    <joint name="lara5_joint2" type="revolute">
        <origin rpy="0 0 -4.8965276278067904e-12" xyz="0 0 0" />
        <axis xyz="1 0 0" />
        <limit effort="204" lower="-2.3492" upper="2.3492" velocity="2.3492" />
        <parent link="lara5_link1" />
        <child link="lara5_link2" />
    </joint>
    <link name="lara5_link2">
        <inertial>
            <mass value="3.735" />
            <origin rpy="0 0 0" xyz="0.130318 -0.15801 0.0" />
            <inertia ixx="0.091957" ixy="-0.003907" ixz="1e-06" iyy="0.005196" iyz="6e-06" izz="0.090991" />
        </inertial>
        <visual>
            <origin rpy="0 0 0" xyz="0 0 0" />
            <geometry>
                <mesh filename="package://neura_robot_description/lara5/meshes/Link2_body.stl" />
            </geometry>
            <material name="white" />
        </visual>
        <collision>
            <origin rpy="0 0 0" xyz="0 0 0" />
            <geometry>
                <mesh filename="package://neura_robot_description/lara5/collision/Link2_body.stl" />
            </geometry>
            <material name="white" />
        </collision>
    </link>
    <!-- ============================ DOF3 ================================= -->
    <joint name="lara5_joint3" type="revolute">
        <origin rpy="0 0 0" xyz="0 -0.38 0" />
        <axis xyz="1 0 0" />
        <limit effort="107" lower="-2.6093" upper="2.6093" velocity="2.6093" />
        <parent link="lara5_link2" />
        <child link="lara5_link3" />
    </joint>
    <link name="lara5_link3">
        <inertial>
            <mass value="4.715" />
            <origin rpy="0 0 0" xyz="0.01936 -0.041461 2.1e-05" />
            <inertia ixx="0.01631" ixy="-0.003836" ixz="-1e-06" iyy="0.009822" iyz="2e-06" izz="0.020163" />
        </inertial>
        <visual>
            <origin rpy="0 0 0" xyz="0 0 0" />
            <geometry>
                <mesh filename="package://neura_robot_description/lara5/meshes/Link3_body.stl" />
            </geometry>
            <material name="white" />
        </visual>
        <visual>
            <origin rpy="0 0 0" xyz="0 0 0" />
            <geometry>
                <mesh filename="package://neura_robot_description/lara5/meshes/Link3_rings.stl" />
            </geometry>
            <material name="white" />
        </visual>
        <collision>
            <origin rpy="0 0 0" xyz="0 0 0" />
            <geometry>
                <mesh filename="package://neura_robot_description/lara5/collision/Link3_body.stl" />
            </geometry>
            <material name="white" />
        </collision>
    </link>
    <!-- ============================ DOF4 ================================= -->
    <joint name="lara5_joint4" type="revolute">
        <origin rpy="0 0 4.8965276278067904e-12" xyz="0 0 0" />
        <axis xyz="0 -1 0" />
        <limit effort="107" lower="-3.14159" upper="3.14159" velocity="3.14159" />
        <parent link="lara5_link3" />
        <child link="lara5_link4" />
    </joint>
    <link name="lara5_link4">
        <inertial>
            <mass value="1.468" />
            <origin rpy="0 0 0" xyz="0.058796 -0.257035 -4.8e-05" />
            <inertia ixx="0.016761" ixy="0.004792" ixz="2e-06" iyy="0.004072" iyz="-6e-06" izz="0.018771" />
        </inertial>
        <visual>
            <origin rpy="0 0 0" xyz="0 0 0" />
            <geometry>
                <mesh filename="package://neura_robot_description/lara5/meshes/Link4_body.stl" />
            </geometry>
            <material name="white" />
        </visual>
        <collision>
            <origin rpy="0 0 0" xyz="0 0 0" />
            <geometry>
                <mesh filename="package://neura_robot_description/lara5/collision/Link4_body.stl" />
            </geometry>
            <material name="white" />
        </collision>
    </link>
    <!-- ============================ DOF5 ================================= -->
    <joint name="lara5_joint5" type="revolute">
        <origin rpy="0 0 -4.8965276278067904e-12" xyz="0 -0.42 0" />
        <axis xyz="1 0 0" />
        <limit effort="36" lower="-3.14159" upper="3.14159" velocity="3.14159" />
        <parent link="lara5_link4" />
        <child link="lara5_link5" />
    </joint>
    <link name="lara5_link5">
        <inertial>
            <mass value="2.498" />
            <origin rpy="0 0 0" xyz="0.015915 -0.036566 0.0" />
            <inertia ixx="0.006007" ixy="-0.001465" ixz="0.0" iyy="0.003499" iyz="0.0" izz="0.007622" />
        </inertial>
        <visual>
            <origin rpy="0 0 0" xyz="0 0 0" />
            <geometry>
                <mesh filename="package://neura_robot_description/lara5/meshes/Link5_body.stl" />
            </geometry>
            <material name="white" />
        </visual>
        <visual>
            <origin rpy="0 0 0" xyz="0 0 0" />
            <geometry>
                <mesh filename="package://neura_robot_description/lara5/meshes/Link5_rings.stl" />
            </geometry>
            <material name="white" />
        </visual>
        <collision>
            <origin rpy="0 0 0" xyz="0 0 0" />
            <geometry>
                <mesh filename="package://neura_robot_description/lara5/collision/Link5_body.stl" />
            </geometry>
            <material name="white" />
        </collision>
    </link>
    <!-- ============================ DOF6 ================================= -->
    <joint name="lara5_joint6" type="revolute">
        <origin rpy="0 0 4.8965276278067904e-12" xyz="0 0 0" />
        <axis xyz="0 -1 0" />
        <limit effort="36" lower="-3.14159" upper="3.14159" velocity="3.14159" />
        <parent link="lara5_link5" />
        <child link="lara5_link6" />
    </joint>
    <link name="lara5_link6">
        <inertial>
            <mass value="0.455" />
            <origin rpy="0 0 0" xyz="0.000924 -0.14919100000000002 0.000337" />
            <inertia ixx="0.0006" ixy="-4e-06" ixz="-9e-06" iyy="0.000605" iyz="0.0" izz="0.000602" />
        </inertial>
        <visual>
            <origin rpy="0 0 0" xyz="0 0 0" />
            <geometry>
                <mesh filename="package://neura_robot_description/lara5/meshes/Link6_body.stl" />
            </geometry>
            <material name="white" />
        </visual>
        <collision>
            <origin rpy="0 0 0" xyz="0 0 0" />
            <geometry>
                <mesh filename="package://neura_robot_description/lara5/collision/Link6_body.stl" />
            </geometry>
            <material name="white" />
        </collision>
    </link>
    <!-- ============================ Flange ================================= -->
    <link name="lara5_flange" />
    <joint name="lara5_link6_to_flange" type="fixed">
        <origin rpy="1.5707963267948966 1.5707963267948966 0" xyz="0 -0.157 0" />
        <parent link="lara5_link6" />
        <child link="lara5_flange" />
    </joint>
    <link name="world" />
    <joint name="world_joint" type="fixed">
        <parent link="world" />
        <child link="lara5_root_link" />
        <origin rpy="0.0 0.0 0.0" xyz="0.0 0.0 0.0" />
    </joint>
    <transmission name="trans_lara5_joint1">
        <type>transmission_interface/SimpleTransmission</type>
        <joint name="lara5_joint1">
            <hardwareInterface>hardware_interface/EffortJointInterface</hardwareInterface>
        </joint>
        <actuator name="lara5_joint1_motor">
            <hardwareInterface>hardware_interface/EffortJointInterface</hardwareInterface>
            <mechanicalReduction>1</mechanicalReduction>
        </actuator>
    </transmission>
    <transmission name="trans_lara5_joint2">
        <type>transmission_interface/SimpleTransmission</type>
        <joint name="lara5_joint2">
            <hardwareInterface>hardware_interface/EffortJointInterface</hardwareInterface>
        </joint>
        <actuator name="lara5_joint2_motor">
            <hardwareInterface>hardware_interface/EffortJointInterface</hardwareInterface>
            <mechanicalReduction>1</mechanicalReduction>
        </actuator>
    </transmission>
    <transmission name="trans_lara5_joint3">
        <type>transmission_interface/SimpleTransmission</type>
        <joint name="lara5_joint3">
            <hardwareInterface>hardware_interface/EffortJointInterface</hardwareInterface>
        </joint>
        <actuator name="lara5_joint3_motor">
            <hardwareInterface>hardware_interface/EffortJointInterface</hardwareInterface>
            <mechanicalReduction>1</mechanicalReduction>
        </actuator>
    </transmission>
    <transmission name="trans_lara5_joint4">
        <type>transmission_interface/SimpleTransmission</type>
        <joint name="lara5_joint4">
            <hardwareInterface>hardware_interface/EffortJointInterface</hardwareInterface>
        </joint>
        <actuator name="lara5_joint4_motor">
            <hardwareInterface>hardware_interface/EffortJointInterface</hardwareInterface>
            <mechanicalReduction>1</mechanicalReduction>
        </actuator>
    </transmission>
    <transmission name="trans_lara5_joint5">
        <type>transmission_interface/SimpleTransmission</type>
        <joint name="lara5_joint5">
            <hardwareInterface>hardware_interface/EffortJointInterface</hardwareInterface>
        </joint>
        <actuator name="lara5_joint5_motor">
            <hardwareInterface>hardware_interface/EffortJointInterface</hardwareInterface>
            <mechanicalReduction>1</mechanicalReduction>
        </actuator>
    </transmission>
    <transmission name="trans_lara5_joint6">
        <type>transmission_interface/SimpleTransmission</type>
        <joint name="lara5_joint6">
            <hardwareInterface>hardware_interface/EffortJointInterface</hardwareInterface>
        </joint>
        <actuator name="lara5_joint6_motor">
            <hardwareInterface>hardware_interface/EffortJointInterface</hardwareInterface>
            <mechanicalReduction>1</mechanicalReduction>
        </actuator>
    </transmission>
    <gazebo>
        <plugin name="gazebo_ros_control" filename="libgazebo_ros_control.so">
            <robotNamespace>/</robotNamespace>
        </plugin>
    </gazebo>
</robot>

